Workbook

Sheet Cover
B2: DLocal Limited (NASDAQ: DLO)
B3: Equity Research | Initiating Coverage
B5: Payments Infrastructure | Emerging Markets | March 2026
B9: SELL | C9: Price Target: $8.50 | E9: Current Price: $11.61 | G9: Downside: (27%)
B11: INVESTMENT THESIS
B12: ▪ Take Rate Compression | C12: Net take rate has fallen from 1.9% (2022) to 1.2% (2024) as competition intensifies. We model further decline to ~0.9% by 2027E, capping revenue upside despite strong TPV growth of 40%+ near-term.
B13: ▪ Operating Leverage Not Yet Materializing | C13: G&A grew 43% in 2024 vs revenue growth of 15%. Operating margin compressed from 31% to 19%. Cost discipline remains the key execution risk and is not yet visible in the numbers.
B14: ▪ Valuation Offers No Margin of Safety | C14: DCF (WACC 12.2%, TGR 3.5%) yields $8.33/share. Stock trades at 4.6x EV/Revenue vs peer median of 2.5x. At $11.61 we see 27% downside with limited upside catalysts in the near term.
B16: FINANCIAL SUMMARY (USD $000s)
C17: 2022A | D17: 2023A | E17: 2024A | F17: 2025E | G17: 2026E
B18: Revenue | C18: ='Income Statement'!C6 -> 418925 | D18: ='Income Statement'!D6 -> 650351 | E18: ='Income Statement'!E6 -> 745974 | F18: ='Income Statement'!F6 -> 984637.5 | G18: ='Income Statement'!G6 -> 1243006.4
B19: Gross Profit | C19: ='Income Statement'!C8 -> 202167 | D19: ='Income Statement'!D8 -> 276859 | E19: ='Income Statement'!E8 -> 294673 | F19: ='Income Statement'!F8 -> 368791.5 | G19: ='Income Statement'!G8 -> 448994.7
B20: Gross Margin % | C20: ='Income Statement'!C9 -> 0.48258519 | D20: ='Income Statement'!D9 -> 0.42570704 | E20: ='Income Statement'!E9 -> 0.39501779 | F20: ='Income Statement'!F9 -> 0.37454545 | G20: ='Income Statement'!G9 -> 0.36121673
B21: Operating Income | C21: ='Income Statement'!C16 -> 127910 | D21: ='Income Statement'!D16 -> 179657 | E21: ='Income Statement'!E16 -> 140500 | F21: ='Income Statement'!F16 -> 182819.53 | G21: ='Income Statement'!G16 -> 227396.21
B22: Net Income | C22: ='Income Statement'!C25 -> 108697 | D22: ='Income Statement'!D25 -> 149086 | E22: ='Income Statement'!E25 -> 120469 | F22: ='Income Statement'!F25 -> 149167.43 | G22: ='Income Statement'!G25 -> 175809.05
B23: Net Margin % | C23: ='Income Statement'!C26 -> 0.25946649 | D23: ='Income Statement'!D26 -> 0.22923929 | E23: ='Income Statement'!E26 -> 0.16149222 | F23: ='Income Statement'!F26 -> 0.15149477 | G23: ='Income Statement'!G26 -> 0.14143857
B25: VALUATION SUMMARY
B26: Method | C26: Implied Price | D26: Weight
B27: DCF — Base Case | C27: 8.33 | D27: 0.5
B28: EV/Revenue — Peer Median | C28: 6.44 | D28: 0.25
B29: EV/EBITDA — Peer Median | C29: 8.67 | D29: 0.25
B30: KEY RISKS TO THESIS
B31: Upside Risk | C31: Take rate stabilization or faster expansion in Africa/SE Asia could drive significant revenue upside vs base case.
B32: Downside Risk | C32: Macro deterioration in Brazil/Argentina (60%+ of TPV) or regulatory changes to cross-border payments.
B33: Regulatory Risk | C33: Emerging market payment regulations remain fluid. New restrictions could structurally impair the business model.
B36: By: Prakhar Srivastava | NYU | MS Information System Management | Corporate Finance | F36: Linkedin

Sheet Assumptions
B1: Dlocal Limited (NASDAQ: DLO) | L1: SCENARIO SELECTOR
B2: Assumptions & Drivers | L2: Base
B3: All figured in USD thousands unless stated | L3: ← Select scenario here
C5: 2022A | D5: 2023A | E5: 2024A | F5: 2025E | G5: 2026E | H5: 2027E | I5: 2028E | J5: 2029E
B6: TPV & REVENUE DRIVERS
B7: Total Payment Volume (TPV) $M | C7: 10567 | D7: 17677 | E7: 25575 | F7: =E7*(1+F20) -> 35805 | G7: =F7*(1+G20) -> 47262.6 | H7: =G7*(1+H20) -> 59550.876 | I7: =H7*(1+I20) -> 71461.051 | J7: =I7*(1+J20) -> 83609.43
B8: YoY TPV Growth % | D8: 0.6731 | E8: 0.4472 | F8: =F20 -> 0.4 | G8: =G20 -> 0.32 | H8: =H20 -> 0.26 | I8: =I20 -> 0.2 | J8: =J20 -> 0.17
B9: Gross Take Rate % | C9: 0.03964 | D9: 0.03679 | E9: 0.02917 | F9: =F25 -> 0.0275 | G9: =G25 -> 0.0263 | H9: =H25 -> 0.0255 | I9: =I25 -> 0.0252 | J9: =J25 -> 0.025
B10: Net Take Rate % | C10: 0.01913 | D10: 0.01566 | E10: 0.01152 | F10: =F30 -> 0.0103 | G10: =G30 -> 0.0095 | H10: =H30 -> 0.009 | I10: =I30 -> 0.009 | J10: =J30 -> 0.009
B11: Revenue ($000s) | C11: 418925 | D11: 650351 | E11: 745974 | F11: =F13 -> 984637.5 | G11: =G13 -> 1243006.4 | H11: =H13 -> 1518547.3 | I11: =I13 -> 1800818.5 | J11: =J13 -> 2090235.7
B12: Gross Profit ($000s) | C12: 202167 | D12: 276859 | E12: 294673 | F12: =F7*1000*F30 -> 368791.5 | G12: =G7*1000*G30 -> 448994.7 | H12: =H7*1000*H30 -> 535957.88 | I12: =I7*1000*I30 -> 643149.46 | J12: =J7*1000*J30 -> 752484.87
B13: Revenue Check (TPV × GTR) | C13: =C7*1000*C9 -> 418875.88 | D13: =D7*1000*D9 -> 650336.83 | E13: =E7*1000*E9 -> 746022.75 | F13: =F7*1000*F9 -> 984637.5 | G13: =G7*1000*G9 -> 1243006.4 | H13: =H7*1000*H9 -> 1518547.3 | I13: =I7*1000*I9 -> 1800818.5 | J13: =J7*1000*J9 -> 2090235.7
B15: FORECAST ASSUMPTIONS
B16: Active Scenario | F16: =$L$2 -> Base | G16: =$L$2 -> Base | H16: =$L$2 -> Base | I16: =$L$2 -> Base | J16: =$L$2 -> Base
B17: TPV Growth % (Base) | F17: 0.4 | G17: 0.32 | H17: 0.26 | I17: 0.2 | J17: 0.17
B18: TPV Growth % (Bull) | F18: 0.5 | G18: 0.42 | H18: 0.34 | I18: 0.26 | J18: 0.22
B19: TPV Growth % (Bear) | F19: 0.33 | G19: 0.22 | H19: 0.17 | I19: 0.13 | J19: 0.1
B20: TPV Growth % (Active) | F20: =IF($L$2="Bull",F18,IF($L$2="Bear",F19,F17)) -> 0.4 | G20: =IF($L$2="Bull",G18,IF($L$2="Bear",G19,G17)) -> 0.32 | H20: =IF($L$2="Bull",H18,IF($L$2="Bear",H19,H17)) -> 0.26 | I20: =IF($L$2="Bull",I18,IF($L$2="Bear",I19,I17)) -> 0.2 | J20: =IF($L$2="Bull",J18,IF($L$2="Bear",J19,J17)) -> 0.17
B21: TAKE RATE ASSUMPTIONS
B22: Gross Take Rate (Base) | C22: 0.0396 | D22: 0.0368 | E22: 0.0292 | F22: 0.0275 | G22: 0.0263 | H22: 0.0255 | I22: 0.0252 | J22: 0.025
B23: Gross Take Rate (Bull) | C23: 0.0396 | D23: 0.0368 | E23: 0.0292 | F23: 0.028 | G23: 0.0272 | H23: 0.0267 | I23: 0.0265 | J23: 0.0263
B24: Gross Take Rate (Bear) | C24: 0.0396 | D24: 0.0368 | E24: 0.0292 | F24: 0.0265 | G24: 0.025 | H24: 0.024 | I24: 0.0235 | J24: 0.0232
B25: Gross Take Rate (Active) | C25: 0.0396 | D25: 0.0368 | E25: 0.0292 | F25: =IF($L$2="Bull",F23,IF($L$2="Bear",F24,F22)) -> 0.0275 | G25: =IF($L$2="Bull",G23,IF($L$2="Bear",G24,G22)) -> 0.0263 | H25: =IF($L$2="Bull",H23,IF($L$2="Bear",H24,H22)) -> 0.0255 | I25: =IF($L$2="Bull",I23,IF($L$2="Bear",I24,I22)) -> 0.0252 | J25: =IF($L$2="Bull",J23,IF($L$2="Bear",J24,J22)) -> 0.025
B26: Spread (Base) | C26: 0.0205 | D26: 0.0211 | E26: 0.0176 | F26: 0.0172 | G26: 0.0168 | H26: 0.0165 | I26: 0.0162 | J26: 0.016
B27: Spread (Bull) | C27: 0.0205 | D27: 0.0211 | E27: 0.0176 | F27: 0.017 | G27: 0.0167 | H27: 0.0165 | I27: 0.0163 | J27: 0.016
B28: Spread (Bear) | C28: 0.0205 | D28: 0.0211 | E28: 0.0176 | F28: 0.0174 | G28: 0.017 | H28: 0.0163 | I28: 0.016 | J28: 0.0158
B29: Spread (Active) | C29: 0.0205 | D29: 0.0211 | E29: 0.0176 | F29: =IF($L$2="Bull",F27,IF($L$2="Bear",F28,F26)) -> 0.0172 | G29: =IF($L$2="Bull",G27,IF($L$2="Bear",G28,G26)) -> 0.0168 | H29: =IF($L$2="Bull",H27,IF($L$2="Bear",H28,H26)) -> 0.0165 | I29: =IF($L$2="Bull",I27,IF($L$2="Bear",I28,I26)) -> 0.0162 | J29: =IF($L$2="Bull",J27,IF($L$2="Bear",J28,J26)) -> 0.016
B30: Net Take Rate (Active) | C30: =C25-C29 -> 0.0191 | D30: =D25-D29 -> 0.0157 | E30: =E25-E29 -> 0.0116 | F30: =F25-F29 -> 0.0103 | G30: =G25-G29 -> 0.0095 | H30: =H25-H29 -> 0.009 | I30: =I25-I29 -> 0.009 | J30: =J25-J29 -> 0.009
B31: Net Take Rate (Base) | C31: =C22-C26 -> 0.0191 | D31: =D22-D26 -> 0.0157 | E31: =E22-E26 -> 0.0116 | F31: =F22-F26 -> 0.0103 | G31: =G22-G26 -> 0.0095 | H31: =H22-H26 -> 0.009 | I31: =I22-I26 -> 0.009 | J31: =J22-J26 -> 0.009
B32: Net Take Rate (Bull) | C32: =C23-C27 -> 0.0191 | D32: =D23-D27 -> 0.0157 | E32: =E23-E27 -> 0.0116 | F32: =F23-F27 -> 0.011 | G32: =G23-G27 -> 0.0105 | H32: =H23-H27 -> 0.0102 | I32: =I23-I27 -> 0.0102 | J32: =J23-J27 -> 0.0103
B33: Net Take Rate (Bear) | C33: =C24-C28 -> 0.0191 | D33: =D24-D28 -> 0.0157 | E33: =E24-E28 -> 0.0116 | F33: =F24-F28 -> 0.0091 | G33: =G24-G28 -> 0.008 | H33: =H24-H28 -> 0.0077 | I33: =I24-I28 -> 0.0075 | J33: =J24-J28 -> 0.0074
B34: OPEX ASSUMPTIONS
B35: Tech & Dev Growth % | D35: 0.993 | E35: 1.026 | F35: 0.35 | G35: 0.25 | H35: 0.2 | I35: 0.18 | J35: 0.15
B36: Sales & Marketing Growth % | D36: 0.284 | E36: 0.263 | F36: 0.22 | G36: 0.18 | H36: 0.15 | I36: 0.12 | J36: 0.1
B37: G&A Growth % | D37: 0.459 | E37: 0.435 | F37: 0.22 | G37: 0.18 | H37: 0.15 | I37: 0.12 | J37: 0.1
B38: Impairment ($000s) | C38: -5534 | D38: 3136 | E38: -440 | F38: -500 | G38: -500 | H38: -500 | I38: -500 | J38: -500
B39: Other Operating Loss ($000s) | C39: -697 | D39: 0 | E39: -5257 | F39: -1000 | G39: -1000 | H39: -1000 | I39: -1000 | J39: -1000
B41: BELOW THE LINE ASSUMPTIONS
B42: Finance Income ($000s) | C42: 18078 | D42: 128228 | E42: 66875 | F42: 35000 | G42: 20000 | H42: 15000 | I42: 12000 | J42: 10000
B43: Finance Costs ($000s) | C43: -24668 | D43: -116834 | E43: -49701 | F43: -25000 | G43: -20000 | H43: -15000 | I43: -12000 | J43: -10000
...

Sheet Income Statement
B1: DLocal Limited (NASDAQ: DLO)
B2: Consolidated Income Statement
B3: All figures in USD thousands unless stated
C5: 2022A | D5: 2023A | E5: 2024A | F5: 2025E | G5: 2026E | H5: 2027E | I5: 2028E | J5: 2029E
B6: Revenue | C6: 418925 | D6: 650351 | E6: 745974 | F6: =Assumptions!F11 -> 984637.5 | G6: =Assumptions!G11 -> 1243006.4 | H6: =Assumptions!H11 -> 1518547.3 | I6: =Assumptions!I11 -> 1800818.5 | J6: =Assumptions!J11 -> 2090235.7
B7: Cost of Revenue | C7: -216758 | D7: -373492 | E7: -451301 | F7: =Assumptions!F12-Assumptions!F11 -> -615846 | G7: =Assumptions!G12-Assumptions!G11 -> -794011.68 | H7: =Assumptions!H12-Assumptions!H11 -> -982589.45 | I7: =Assumptions!I12-Assumptions!I11 -> -1157669 | J7: =Assumptions!J12-Assumptions!J11 -> -1337750.9
B8: Gross Profit | C8: =C6+C7 -> 202167 | D8: =D6+D7 -> 276859 | E8: =E6+E7 -> 294673 | F8: =F6+F7 -> 368791.5 | G8: =G6+G7 -> 448994.7 | H8: =H6+H7 -> 535957.88 | I8: =I6+I7 -> 643149.46 | J8: =J6+J7 -> 752484.87
B9: Gross Margin % | C9: =C8/C6 -> 0.48258519 | D9: =D8/D6 -> 0.42570704 | E9: =E8/E6 -> 0.39501779 | F9: =F8/F6 -> 0.37454545 | G9: =G8/G6 -> 0.36121673 | H9: =H8/H6 -> 0.35294118 | I9: =I8/I6 -> 0.35714286 | J9: =J8/J6 -> 0.36
B11: Technology & Development | C11: -6348 | D11: -12650 | E11: -25625 | F11: =E11*(1+Assumptions!F35) -> -34593.75 | G11: =F11*(1+Assumptions!G35) -> -43242.188 | H11: =G11*(1+Assumptions!H35) -> -51890.625 | I11: =H11*(1+Assumptions!I35) -> -61230.938 | J11: =I11*(1+Assumptions!J35) -> -70415.578
B12: Sales & Marketing | C12: -13335 | D12: -17120 | E12: -21626 | F12: =E12*(1+Assumptions!F36) -> -26383.72 | G12: =F12*(1+Assumptions!G36) -> -31132.79 | H12: =G12*(1+Assumptions!H36) -> -35802.708 | I12: =H12*(1+Assumptions!I36) -> -40099.033 | J12: =I12*(1+Assumptions!J36) -> -44108.936
B13: General & Administrative | C13: -48343 | D13: -70568 | E13: -101225 | F13: =E13*(1+Assumptions!F37) -> -123494.5 | G13: =F13*(1+Assumptions!G37) -> -145723.51 | H13: =G13*(1+Assumptions!H37) -> -167582.04 | I13: =H13*(1+Assumptions!I37) -> -187691.88 | J13: =I13*(1+Assumptions!J37) -> -206461.07
B14: Impairment | C14: -5534 | D14: 3136 | E14: -440 | F14: =Assumptions!F38 -> -500 | G14: =Assumptions!G38 -> -500 | H14: =Assumptions!H38 -> -500 | I14: =Assumptions!I38 -> -500 | J14: =Assumptions!J38 -> -500
B15: Other Operating Loss | C15: -697 | D15: 0 | E15: -5257 | F15: =Assumptions!F39 -> -1000 | G15: =Assumptions!G39 -> -1000 | H15: =Assumptions!H39 -> -1000 | I15: =Assumptions!I39 -> -1000 | J15: =Assumptions!J39 -> -1000
B16: Operating Income | C16: =C8+C11+C12+C13+C14+C15 -> 127910 | D16: =D8+D11+D12+D13+D14+D15 -> 179657 | E16: =E8+E11+E12+E13+E14+E15 -> 140500 | F16: =F8+F11+F12+F13+F14+F15 -> 182819.53 | G16: =G8+G11+G12+G13+G14+G15 -> 227396.21 | H16: =H8+H11+H12+H13+H14+H15 -> 279182.51 | I16: =I8+I11+I12+I13+I14+I15 -> 352627.61 | J16: =J8+J11+J12+J13+J14+J15 -> 429999.29
B17: Operating Margin % | C17: =C16/C6 -> 0.30532912 | D17: =D16/D6 -> 0.27624621 | E17: =E16/E6 -> 0.18834437 | F17: =F16/F6 -> 0.18567191 | G17: =G16/G6 -> 0.1829405 | H17: =H16/H6 -> 0.18384841 | I17: =I16/I6 -> 0.19581519 | J17: =J16/J6 -> 0.20571808
B19: Finance Income | C19: 18078 | D19: 128228 | E19: 66875 | F19: =Assumptions!F42 -> 35000 | G19: =Assumptions!G42 -> 20000 | H19: =Assumptions!H42 -> 15000 | I19: =Assumptions!I42 -> 12000 | J19: =Assumptions!J42 -> 10000
B20: Finance Costs | C20: -24668 | D20: -116834 | E20: -49701 | F20: =Assumptions!F43 -> -25000 | G20: =Assumptions!G43 -> -20000 | H20: =Assumptions!H43 -> -15000 | I20: =Assumptions!I43 -> -12000 | J20: =Assumptions!J43 -> -10000
B21: Inflation Adjustment | C21: -1037 | D21: -12537 | E21: -6655 | F21: =Assumptions!F44 -> -4000 | G21: =Assumptions!G44 -> -2000 | H21: =Assumptions!H44 -> -1000 | I21: =Assumptions!I44 -> -500 | J21: =Assumptions!J44 -> -500
B22: Net Other Results | C22: =C19+C20+C21 -> -7627 | D22: =D19+D20+D21 -> -1143 | E22: =E19+E20+E21 -> 10519 | F22: =F19+F20+F21 -> 6000 | G22: =G19+G20+G21 -> -2000 | H22: =H19+H20+H21 -> -1000 | I22: =I19+I20+I21 -> -500 | J22: =J19+J20+J21 -> -500
B23: Profit Before Tax | C23: =C16+C19+C20+C21 -> 120283 | D23: =D16+D19+D20+D21 -> 178514 | E23: =E16+E19+E20+E21 -> 151019 | F23: =F16+F19+F20+F21 -> 188819.53 | G23: =G16+G19+G20+G21 -> 225396.21 | H23: =H16+H19+H20+H21 -> 278182.51 | I23: =I16+I19+I20+I21 -> 352127.61 | J23: =J16+J19+J20+J21 -> 429499.29
B24: Income Tax | C24: -11586 | D24: -29428 | E24: -30550 | F24: =-F23*Assumptions!F45 -> -39652.101 | G24: =-G23*Assumptions!G45 -> -49587.167 | H24: =-H23*Assumptions!H45 -> -61200.153 | I24: =-I23*Assumptions!I45 -> -80989.35 | J24: =-J23*Assumptions!J45 -> -98784.836
B25: Net Income | C25: =C23+C24 -> 108697 | D25: =D23+D24 -> 149086 | E25: =E23+E24 -> 120469 | F25: =F23+F24 -> 149167.43 | G25: =G23+G24 -> 175809.05 | H25: =H23+H24 -> 216982.36 | I25: =I23+I24 -> 271138.26 | J25: =J23+J24 -> 330714.45
B26: Net Profit Margin % | C26: =C25/C6 -> 0.25946649 | D26: =D25/D6 -> 0.22923929 | E26: =E25/E6 -> 0.16149222 | F26: =F25/F6 -> 0.15149477 | G26: =G25/G6 -> 0.14143857 | H26: =H25/H6 -> 0.14288811 | I26: =I25/I6 -> 0.1505639 | J26: =J25/J6 -> 0.15821873

Sheet Balance Sheet
B1: DLocal Limited (NASDAQ: DLO)
B2: Consolidated Balance Sheet
B3: All figures in USD thousands unless stated
C5: 2022A | D5: 2023A | E5: 2024A | F5: 2025E | G5: 2026E | H5: 2027E | I5: 2028E | J5: 2029E
B6: ASSETS
B7: Cash and Cash Equivalents | C7: 468092 | D7: 536160 | E7: 425172 | F7: ='Cash Flow'!F32 -> 534252.01 | G7: ='Cash Flow'!G32 -> 638944.74 | H7: ='Cash Flow'!H32 -> 785293.71 | I7: ='Cash Flow'!I32 -> 974508.85 | J7: ='Cash Flow'!J32 -> 1193309
B8: Trade and Other Receivables | C8: 240446 | D8: 363374 | E8: 496713 | F8: =(Assumptions!F48*Assumptions!F11)/365 -> 566503.77 | G8: =(Assumptions!G48*Assumptions!G11)/365 -> 664071.9 | H8: =(Assumptions!H48*Assumptions!H11)/365 -> 769674.68 | I8: =(Assumptions!I48*Assumptions!I11)/365 -> 888074.87 | J8: =(Assumptions!J48*Assumptions!J11)/365 -> 1030801.2
B9: Financial Assets at Fair Value | C9: 1295 | D9: 102677 | E9: 129319 | F9: =Assumptions!F50 -> 50000 | G9: =Assumptions!G50 -> 20000 | H9: =Assumptions!H50 -> 10000 | I9: =Assumptions!I50 -> 5000 | J9: =Assumptions!J50 -> 5000
B10: Other Current Assets | C10: 57995 | D10: 13822 | E10: 21679 | F10: =Assumptions!F52 -> 23846.9 | G10: =Assumptions!G52 -> 26231.59 | H10: =Assumptions!H52 -> 28854.749 | I10: =Assumptions!I52 -> 31740.224 | J10: =Assumptions!J52 -> 34914.246
B11: Total Current Assets | C11: =C7+C8+C9+C10 -> 767828 | D11: =D7+D8+D9+D10 -> 1016033 | E11: =E7+E8+E9+E10 -> 1072883 | F11: =F7+F8+F9+F10 -> 1174602.7 | G11: =G7+G8+G9+G10 -> 1349248.2 | H11: =H7+H8+H9+H10 -> 1593823.1 | I11: =I7+I8+I9+I10 -> 1899323.9 | J11: =J7+J8+J9+J10 -> 2264024.4
B12: Right of Use Assets | C12: 3934 | D12: 3689 | E12: 3645 | F12: =E12*0.95 -> 3462.75 | G12: =F12*0.95 -> 3289.6125 | H12: =G12*0.95 -> 3125.1319 | I12: =H12*0.95 -> 2968.8753 | J12: =I12*0.95 -> 2820.4315
B13: Other Non-Current Assets | C13: 54539 | D13: 64731 | E13: 94801 | F13: =Assumptions!F53 -> 102385.08 | G13: =Assumptions!G53 -> 110575.89 | H13: =Assumptions!H53 -> 119421.96 | I13: =Assumptions!I53 -> 128975.71 | J13: =Assumptions!J53 -> 139293.77
B14: Total Non-Current Assets | C14: =C12+C13 -> 58473 | D14: =D12+D13 -> 68420 | E14: =E12+E13 -> 98446 | F14: =F12+F13 -> 105847.83 | G14: =G12+G13 -> 113865.5 | H14: =H12+H13 -> 122547.09 | I14: =I12+I13 -> 131944.59 | J14: =J12+J13 -> 142114.2
B15: TOTAL ASSETS | C15: =C11+C14 -> 826301 | D15: =D11+D14 -> 1084453 | E15: =E11+E14 -> 1171329 | F15: =F11+F14 -> 1280450.5 | G15: =G11+G14 -> 1463113.7 | H15: =H11+H14 -> 1716370.2 | I15: =I11+I14 -> 2031268.5 | J15: =J11+J14 -> 2406138.6
B17: LIABILITIES
B18: Trade and Other Payables | C18: 407874 | D18: 602493 | E18: 597787 | F18: =Assumptions!F11*Assumptions!F49 -> 708939 | G18: =Assumptions!G11*Assumptions!G49 -> 807954.15 | H18: =Assumptions!H11*Assumptions!H49 -> 911128.4 | I18: =Assumptions!I11*Assumptions!I49 -> 1026466.5 | J18: =Assumptions!J11*Assumptions!J49 -> 1149629.7
B19: Financial Liabilities | C19: 0 | D19: 0 | E19: 50455 | F19: 25000 | G19: 0 | H19: 0 | I19: 0 | J19: 0
B20: Other Current Liabilities | C20: 14398 | D20: 22736 | E20: 29379 | F20: =E20*(1+0.15) -> 33785.85 | G20: =F20*(1+0.15) -> 38853.727 | H20: =G20*(1+0.15) -> 44681.787 | I20: =H20*(1+0.15) -> 51384.055 | J20: =I20*(1+0.15) -> 59091.663
B21: Total Current Liabilities | C21: =C18+C20 -> 422272 | D21: =D18+D20 -> 625229 | E21: =E18+E19+E20 -> 677621 | F21: =F18+F19+F20 -> 767724.85 | G21: =G18+G19+G20 -> 846807.87 | H21: =H18+H19+H20 -> 955810.19 | I21: =I18+I19+I20 -> 1077850.6 | J21: =J18+J19+J20 -> 1208721.3
B22: Lease Liabilities | C22: 3393 | D22: 3331 | E22: 2863 | F22: =E22*0.9 -> 2576.7 | G22: =F22*0.9 -> 2319.03 | H22: =G22*0.9 -> 2087.127 | I22: =H22*0.9 -> 1878.4143 | J22: =I22*0.9 -> 1690.5729
B23: Other Non-Current Liabilities | C23: 1016 | D23: 753 | E23: 1858 | F23: =E23*1.05 -> 1950.9 | G23: =F23*1.05 -> 2048.445 | H23: =G23*1.05 -> 2150.8673 | I23: =H23*1.05 -> 2258.4106 | J23: =I23*1.05 -> 2371.3311
B24: Total Non-Current Liabilities | C24: =C22+C23 -> 4409 | D24: =D22+D23 -> 4084 | E24: =E22+E23 -> 4721 | F24: =F22+F23 -> 4527.6 | G24: =G22+G23 -> 4367.475 | H24: =H22+H23 -> 4237.9943 | I24: =I22+I23 -> 4136.8249 | J24: =J22+J23 -> 4061.904
B25: TOTAL LIABILITIES | C25: =+C21+C24 -> 426681 | D25: =+D21+D24 -> 629313 | E25: =+E21+E24 -> 682342 | F25: =+F21+F24 -> 772252.45 | G25: =+G21+G24 -> 851175.35 | H25: =+H21+H24 -> 960048.18 | I25: =+I21+I24 -> 1081987.4 | J25: =+J21+J24 -> 1212783.2
B27: EQUITY
B28: Share Capital and Premium | C28: 164899 | D28: 173592 | E28: 187339 | F28: =E28 + (E28 * 0.02) -> 191085.78 | G28: =F28 + (F28 * 0.02) -> 194907.5 | H28: =G28 + (G28 * 0.02) -> 198805.65 | I28: =H28 + (H28 * 0.02) -> 202781.76 | J28: =I28 + (I28 * 0.02) -> 206837.39
B29: Retained Earnings | C29: 219993 | D29: 369608 | E29: 490024 | F29: =E29+'Income Statement'!F25 -> 639191.43 | G29: =F29+'Income Statement'!G25 -> 815000.47 | H29: =G29+'Income Statement'!H25 -> 1031982.8 | I29: =H29+'Income Statement'!I25 -> 1303121.1 | J29: =I29+'Income Statement'!J25 -> 1633835.5
B30: Other Reserves | C30: 14737 | D30: 11767 | E30: 12504 | F30: =E30*1.05 -> 13129.2 | G30: =F30*1.05 -> 13785.66 | H30: =G30*1.05 -> 14474.943 | I30: =H30*1.05 -> 15198.69 | J30: =I30*1.05 -> 15958.625
B31: Treasury Shares | C31: 0 | D31: -99936 | E31: -200980 | F31: =E31+Assumptions!F51 -> -250980 | G31: =F31+Assumptions!G51 -> -290980 | H31: =G31+Assumptions!H51 -> -320980 | I31: =H31+Assumptions!I51 -> -345980 | J31: =I31+Assumptions!J51 -> -370980
B32: Non-Controlling Interest | C32: -9 | D32: 109 | E32: 100 | F32: =E32 -> 100 | G32: =F32 -> 100 | H32: =G32 -> 100 | I32: =H32 -> 100 | J32: =I32 -> 100
B33: Other Equity Movements | C33: 0 | D33: 0 | E33: 0 | F33: =F15-F25-F28-F29-F30-F31-F32 -> -84328.351 | G33: =G15-G25-G28-G29-G30-G31-G32 -> -120875.24 | H33: =H15-H25-H28-H29-H30-H31-H32 -> -168061.38 | I33: =I15-I25-I28-I29-I30-I31-I32 -> -225940.43 | J33: =J15-J25-J28-J29-J30-J31-J32 -> -292396.16 | L33: <-captures SBC reclassifications and OCI items not explicitly modelled.
B34: TOTAL EQUITY | C34: =C28+C29+C30+C31+C32 -> 399620 | D34: =D28+D29+D30+D31+D32 -> 455140 | E34: =E28+E29+E30+E31+E32 -> 488987 | F34: =F28+F29+F30+F31+F32+F33 -> 508198.06 | G34: =G28+G29+G30+G31+G32+G33 -> 611938.39 | H34: =H28+H29+H30+H31+H32+H33 -> 756322.05 | I34: =I28+I29+I30+I31+I32+I33 -> 949281.11 | J34: =J28+J29+J30+J31+J32+J33 -> 1193355.4
B36: TOTAL LIABILITIES AND EQUITY | C36: =C25+C34 -> 826301 | D36: =D25+D34 -> 1084453 | E36: =E25+E34 -> 1171329 | F36: =F25+F34 -> 1280450.5 | G36: =G25+G34 -> 1463113.7 | H36: =H25+H34 -> 1716370.2 | I36: =I25+I34 -> 2031268.5 | J36: =J25+J34 -> 2406138.6
B38: CHECK: Assets - Liabilities - Equity | C38: =C15-C25-C34 -> 0 | D38: =D15-D25-D34 -> 0 | E38: =E15-E25-E34 -> 0 | F38: =F15-F25-F34 -> 0 | G38: =G15-G25-G34 -> 0 | H38: =H15-H25-H34 -> 0 | I38: =I15-I25-I34 -> 0 | J38: =J15-J25-J34 -> 0

Sheet Cash Flow
B1: DLocal Limited (NASDAQ: DLO)
B2: Consolidated Cash Flow Statement
B3: All figures in USD thousands unless stated
C5: 2022A | D5: 2023A | E5: 2024A | F5: 2025E | G5: 2026E | H5: 2027E | I5: 2028E | J5: 2029E
B6: OPERATING ACTIVITIES
B7: Net Income | C7: ='Income Statement'!C25 -> 108697 | D7: ='Income Statement'!D25 -> 149086 | E7: ='Income Statement'!E25 -> 120469 | F7: ='Income Statement'!F25 -> 149167.43 | G7: ='Income Statement'!G25 -> 175809.05 | H7: ='Income Statement'!H25 -> 216982.36 | I7: ='Income Statement'!I25 -> 271138.26 | J7: ='Income Statement'!J25 -> 330714.45
B8: Depreciation & Amortization | C8: - | D8: 12225 | E8: 17395 | F8: =E8*1.15 -> 20004.25 | G8: =F8*1.15 -> 23004.887 | H8: =G8*1.15 -> 26455.621 | I8: =H8*1.15 -> 30423.964 | J8: =I8*1.15 -> 34987.558
B9: Stock Based Compensation | C9: - | D9: 11922 | E9: 23780 | F9: =E9*1.1 -> 26158 | G9: =F9*1.1 -> 28773.8 | H9: =G9*1.1 -> 31651.18 | I9: =H9*1.1 -> 34816.298 | J9: =I9*1.1 -> 38297.928
B10: Fair Value Gains on Financial Assets | C10: - | D10: -78640 | E10: -37416 | F10: -15000 | G10: -8000 | H10: -4000 | I10: -2000 | J10: =-(Assumptions!J50-Assumptions!I50) -> 0
B11: Change in Trade Receivables | C11: - | D11: -123246 | E11: -162645 | F11: =-('Balance Sheet'!F8-'Balance Sheet'!E8) -> -69790.767 | G11: =-('Balance Sheet'!G8-'Balance Sheet'!F8) -> -97568.135 | H11: =-('Balance Sheet'!H8-'Balance Sheet'!G8) -> -105602.78 | I11: =-('Balance Sheet'!I8-'Balance Sheet'!H8) -> -118400.19 | J11: =-('Balance Sheet'!J8-'Balance Sheet'!I8) -> -142726.32
B12: Change in Trade Payables | C12: - | D12: 194619 | E12: -6957 | F12: ='Balance Sheet'!F18-'Balance Sheet'!E18 -> 111152 | G12: ='Balance Sheet'!G18-'Balance Sheet'!F18 -> 99015.147 | H12: ='Balance Sheet'!H18-'Balance Sheet'!G18 -> 103174.26 | I12: ='Balance Sheet'!I18-'Balance Sheet'!H18 -> 115338.14 | J12: ='Balance Sheet'!J18-'Balance Sheet'!I18 -> 123163.12
B13: Other Operating Items (plug) | C13: - | D13: 138962 | E13: 41286 | F13: 10000 | G13: 10001 | H13: 10002 | I13: 10003 | J13: 10004
B14: Income Tax Paid | C14: - | D14: -11475 | E14: -28696 | F14: ='Income Statement'!F24 -> -39652.101 | G14: ='Income Statement'!G24 -> -49587.167 | H14: ='Income Statement'!H24 -> -61200.153 | I14: ='Income Statement'!I24 -> -80989.35 | J14: ='Income Statement'!J24 -> -98784.836
B15: Net Cash from Operations | C15: - | D15: =D7+D8+D9+D10+D11+D12+D13+D14 -> 293453 | E15: =E7+E8+E9+E10+E11+E12+E13+E14 -> -32784 | F15: =F7+F8+F9+F10+F11+F12+F13+F14 -> 192038.81 | G15: =G7+G8+G9+G10+G11+G12+G13+G14 -> 181448.58 | H15: =H7+H8+H9+H10+H11+H12+H13+H14 -> 217462.49 | I15: =I7+I8+I9+I10+I11+I12+I13+I14 -> 260330.11 | J15: =J7+J8+J9+J10+J11+J12+J13+J14 -> 295655.9
B17: INVESTING ACTIVITIES
B18: Capital Expenditure(PP&E) | C18: - | D18: -965 | E18: -1705 | F18: =E18*1.1 -> -1875.5 | G18: =F18*1.1 -> -2063.05 | H18: =G18*1.1 -> -2269.355 | I18: =H18*1.1 -> -2496.2905 | J18: =I18*1.1 -> -2745.9196
B19: Additions of Intangibles (Capitalized Software) | C19: - | D19: -17260 | E19: -20942 | F19: =E19*1.15 -> -24083.3 | G19: =F19*1.15 -> -27695.795 | H19: =G19*1.15 -> -31850.164 | I19: =H19*1.15 -> -36627.689 | J19: =I19*1.15 -> -42121.842
B20: Change in Financial Assets (net) | C20: - | D20: -66442 | E20: 4895 | F20: -5000 | G20: -4999 | H20: -4998 | I20: -4997 | J20: -4996
B21: Net Cash from Investing | D21: =D18+D19+D20 -> -84667 | E21: =E18+E19+E20 -> -17752 | F21: =F18+F19+F20 -> -30958.8 | G21: =G18+G19+G20 -> -34757.845 | H21: =H18+H19+H20 -> -39117.519 | I21: =I18+I19+I20 -> -44120.979 | J21: =J18+J19+J20 -> -49863.762
B23: FINANCING ACTIVITIES
B24: Share Buybacks | C24: - | D24: -97929 | E24: -101067 | F24: =Assumptions!F51 -> -50000 | G24: =Assumptions!G51 -> -40000 | H24: =Assumptions!H51 -> -30000 | I24: =Assumptions!I51 -> -25000 | J24: =Assumptions!J51 -> -25000
B25: Other Financing | C25: - | D25: -35942 | E25: 32480 | F25: -5000 | G25: -4999 | H25: -4998 | I25: -4997 | J25: -4996
B26: Net Cash from Financing | D26: =D24+D25 -> -133871 | E26: =E24+E25 -> -68587 | F26: =F24+F25 -> -55000 | G26: =G24+G25 -> -44999 | H26: =H24+H25 -> -34998 | I26: =I24+I25 -> -29997 | J26: =J24+J25 -> -29996
B28: CASH MOVEMENT
B29: Opening Cash Balance | C29: - | D29: 468092 | E29: =D32 -> 536160 | F29: =E32 -> 425172 | G29: =F32 -> 534252.01 | H29: =G32 -> 638944.74 | I29: =H32 -> 785293.71 | J29: =I32 -> 974508.85
B30: Net Cash Change | C30: - | D30: =D15+D21+D26 -> 74915 | E30: =E15+E21+E26 -> -119123 | F30: =F15+F21+F26 -> 106080.01 | G30: =G15+G21+G26 -> 101691.73 | H30: =H15+H21+H26 -> 143346.97 | I30: =I15+I21+I26 -> 186212.13 | J30: =J15+J21+J26 -> 215796.14
B31: FX Effects on Cash | C31: - | D31: -6847 | E31: 8135 | F31: 3000 | G31: 3001 | H31: 3002 | I31: 3003 | J31: 3004
B32: Closing Cash Balance | D32: =D29+D30+D31 -> 536160 | E32: =E29+E30+E31 -> 425172 | F32: =F29+F30+F31 -> 534252.01 | G32: =G29+G30+G31 -> 638944.74 | H32: =H29+H30+H31 -> 785293.71 | I32: =I29+I30+I31 -> 974508.85 | J32: =J29+J30+J31 -> 1193309
B34: FREE CASH FLOW
B35: Operating Cash Flow | C35: - | D35: =D15 -> 293453 | E35: =E15 -> -32784 | F35: =F15 -> 192038.81 | G35: =G15 -> 181448.58 | H35: =H15 -> 217462.49 | I35: =I15 -> 260330.11 | J35: =J15 -> 295655.9
B36: - Capital Expenditure | C36: - | D36: =D18 -> -965 | E36: =E18 -> -1705 | F36: =F18 -> -1875.5 | G36: =G18 -> -2063.05 | H36: =H18 -> -2269.355 | I36: =I18 -> -2496.2905 | J36: =J18 -> -2745.9196
B37: - Capitalized Software | C37: - | D37: =D19 -> -17260 | E37: =E19 -> -20942 | F37: =F19 -> -24083.3 | G37: =G19 -> -27695.795 | H37: =H19 -> -31850.164 | I37: =I19 -> -36627.689 | J37: =J19 -> -42121.842
B38: = Free Cash Flow | C38: - | D38: =D35+D36+D37 -> 275228 | E38: =E35+E36+E37 -> -55431 | F38: =F35+F36+F37 -> 166080.01 | G38: =G35+G36+G37 -> 151689.73 | H38: =H35+H36+H37 -> 183342.97 | I38: =I35+I36+I37 -> 221206.13 | J38: =J35+J36+J37 -> 250788.14

Sheet DCF
B1: DLocal Limited (NASDAQ: DLO)
B2: Discounted Cashflow Valuation
B3: All figures in USD thousands unless stated
C5: 2022A | D5: 2023A | E5: 2024A | F5: 2025E | G5: 2026E | H5: 2027E | I5: 2028E | J5: 2029E
B6: FCF FORECAST
B7: Free Cash Flow ($000s) | C7: - | D7: - | E7: - | F7: ='Cash Flow'!F38 -> 166080.01 | G7: ='Cash Flow'!G38 -> 151689.73 | H7: ='Cash Flow'!H38 -> 183342.97 | I7: ='Cash Flow'!I38 -> 221206.13 | J7: ='Cash Flow'!J38 -> 250788.14
B8: Discount Period | C8: - | D8: - | E8: - | F8: 0.5 | G8: 1.5 | H8: 2.5 | I8: 3.5 | J8: 4.5
B9: Discount Factor | C9: - | D9: - | E9: - | F9: =1/((1+$C$23)^F8) -> 0.94420753 | G9: =1/((1+$C$23)^G8) -> 0.84178732 | H9: =1/((1+$C$23)^H8) -> 0.75047684 | I9: =1/((1+$C$23)^I8) -> 0.66907101 | J9: =1/((1+$C$23)^J8) -> 0.59649544
B10: Present Value of FCF | C10: - | D10: - | E10: - | F10: =F7*F9 -> 156814 | G10: =G7*G9 -> 127690.49 | H10: =H7*H9 -> 137594.65 | I10: =I7*I9 -> 148002.61 | J10: =J7*J9 -> 149593.98
B11: Sum of PV of FCFs: | C11: =SUM(F10:J10) -> 719695.74
B13: WACC ASSUMPTIONS
B14: Risk Free Rate | C14: 0.043
B15: Equity Risk Premium | C15: 0.055
B16: Beta | C16: 1.45
B17: Cost of Equity | C17: =C14+(C16*C15) -> 0.12275
B18: Cost of Debt (pre-tax) | C18: 0.065
B19: Tax Rate | C19: =Assumptions!F45 -> 0.21
B20: Cost of Debt (post-tax) | C20: =C18*(1-C19) -> 0.05135
B21: Equity Weight | C21: =3542632/(3542632+54412) -> 0.98487313
B22: Debt Weight | C22: =1-C21 -> 0.015126865
B23: WACC | C23: =C21*C17+C22*C20 -> 0.12166994
B25: TERMINAL VALUE
B26: Terminal Growth Rate | C26: 0.035
B27: Terminal Year FCF | C27: ='Cash Flow'!J38*(1+C26) -> 259565.73
B28: Terminal Value | C28: =C27/(C23-C26) -> 2994876
B29: PV of Terminal Value | C29: =C28/(1+C23)^5 -> 1686760.5
B31: VALUATION
B32: PV of FCF Forecast | C32: =F11 -> 0
B33: PV of Terminal Value | C33: =C29 -> 1686760.5
B34: Enterprise Value | C34: =C32+C33 -> 1686760.5
B35: % from Terminal Value | C35: =C33/C34 -> 1
B37: + Cash (own funds only) | C37: 189000
B38: - Total Debt | C38: -54412
B39: Equity Value | C39: =C34+C37+C38 -> 1821348.5
B40: Diluted Shares Outstanding | C40: 305136
B41: Implied Share Price | C41: =C39/C40 -> 5.968973
B42: Current Share Price | C42: 11.61
B43: Upside / Downside | C43: =C41/C42-1 -> -0.48587657
B46: SENSITIVITY ANALYSIS
B47: Implied Share Price
...

Sheet Comps
B1: DLocal Limited (NASDAQ: DLO)
B2: Comparable Company Analysis
B3: All figures in USD thousands unless stated. Market data as of 2026
B6: Company | C6: Share Price | D6: Market Cap ($M) | E6: Net Debt ($M) | F6: Enterprise Value ($M) | G6: Revenue LTM ($M) | H6: EBITDA LTM ($M) | I6: Net Income LTM ($M) | J6: EV/Revenue | K6: EV/EBITDA | L6: P/E | M6: Revenue Growth | N6: EBITDA Margin
B7: DLocal(NASDAQ:DLO) | C7: 11.61 | D7: 3543 | E7: -135 | F7: 3408 | G7: 746 | H7: 158 | I7: 120 | J7: =F7/G7 -> 4.5683646 | K7: =F7/H7 -> 21.56962 | L7: =D7/I7 -> 29.525 | M7: 0.15 | N7: =(H7/G7)*100 -> 21.179625
B8: Payoneer(NASDAQ: PAYO) | C8: 4.99 | D8: 2110 | E8: -400 | F8: 1710 | G8: 990 | H8: 180 | I8: 85 | J8: =F8/G8 -> 1.7272727 | K8: =F8/H8 -> 9.5 | L8: =D8/I8 -> 24.823529 | M8: 0.17 | N8: =(H8/G8)*100 -> 18.181818
B9: Flywire(NASDAQ: FLYW) | C9: 12.04 | D9: 1630 | E9: -200 | F9: 1430 | G9: 583 | H9: 90 | I9: 6 | J9: =F9/G9 -> 2.4528302 | K9: =F9/H9 -> 15.888889 | L9: =D9/I9 -> 271.66667 | M9: 0.46 | N9: =(H9/G9)*100 -> 15.437393
B10: Remitly (NASDAQ: RELY) | C10: 15.99 | D10: 3200 | E10: -300 | F10: 2900 | G10: 1264 | H10: 135 | I10: -37 | J10: =F10/G10 -> 2.2943038 | K10: =F10/H10 -> 21.481481 | L10: N/M | M10: 0.34 | N10: =(H10/G10)*100 -> 10.68038
B11: Adyen (AMS: ADYEN) | D11: 34200 | E11: -2000 | F11: 32200 | G11: 2990 | H11: 1200 | I11: 900 | J11: =F11/G11 -> 10.769231 | K11: =F11/H11 -> 26.833333 | L11: =D11/I11 -> 38 | M11: 0.22 | N11: =(H11/G11)*100 -> 40.133779
B12: Shift4 (NYSE: FOUR) | D12: 7500 | E12: 2500 | F12: 10000 | G12: 2200 | H12: 900 | I12: 280 | J12: =F12/G12 -> 4.5454545 | K12: =F12/H12 -> 11.111111 | L12: =D12/I12 -> 26.785714 | M12: 0.61 | N12: =(H12/G12)*100 -> 40.909091
B14: Mean | J14: =AVERAGE(J8:J13) -> 4.3578184 | K14: =AVERAGE(K8:K13) -> 16.962963 | L14: =AVERAGE(L8,L11,L12) -> 29.869748 | M14: =AVERAGE(M8:M13) -> 0.36
B15: Median | J15: =MEDIAN(J8:J13) -> 2.4528302 | K15: =MEDIAN(K8:K13) -> 15.888889 | L15: =MEDIAN(L8:L13) -> 32.392857 | M15: =MEDIAN(M8:M13) -> 0.34
B17: DLocal Implied Price — EV/Revenue
B18: IMPLIED VALUATION
B19: E/V Revenue - Median Multiple | C19: =(J15*G7+189-54)/305.136 -> 6.4391331
B20: E/V Revenue - Mean Multiple | C20: =(J14*G7+189-54)/305.136 -> 11.09647
B21: E/V EBITDA - Median Multiple | C21: =(K15*H7+189-54)/305.136 -> 8.6697225
B22: E/V EBITDA - Mean Multiple | C22: =(K14*H7+189-54)/305.136 -> 9.2258801
B23: P/E - Mean Multiple | C23: =L14 * (I7/305.136) -> 11.746794
